{"uuid": "8cf0c15a-6518-4b43-9a0b-6e7e6ff84c52", "children": ["5e8e271e-2ada-4de9-aefc-a2652602dbb1"], "befores": [{"name": "web_browser", "status": "passed", "start": 1736902028761, "stop": 1736902030165}], "afters": [{"name": "web_browser::0", "status": "broken", "statusDetails": {"message": "urllib3.exceptions.MaxRetryError: HTTPConnectionPool(host='localhost', port=59895): Max retries exceeded with url: /session/26f219acc028b75dca07a00684a0e921/window (Caused by NewConnectionError('<urllib3.connection.HTTPConnection object at 0x00000207AA596440>: Failed to establish a new connection: [WinError 10061] Подключение не установлено, т.к. конечный компьютер отверг запрос на подключение'))\n", "trace": "  File \"C:\\Users\\Артём\\AppData\\Roaming\\Python\\Python310\\site-packages\\allure_commons\\_allure.py\", line 221, in __call__\n    return self._fixture_function(*args, **kwargs)\n  File \"C:\\Users\\Артём\\AppData\\Roaming\\Python\\Python310\\site-packages\\_pytest\\fixtures.py\", line 907, in _teardown_yield_fixture\n    next(it)\n  File \"C:\\Users\\Артём\\PycharmProjects\\Diplom_Vlada\\conftest.py\", line 41, in web_browser\n    browser.close()\n  File \"C:\\Users\\Артём\\AppData\\Roaming\\Python\\Python310\\site-packages\\selenium\\webdriver\\remote\\webdriver.py\", line 491, in close\n    self.execute(Command.CLOSE)\n  File \"C:\\Users\\Артём\\AppData\\Roaming\\Python\\Python310\\site-packages\\selenium\\webdriver\\remote\\webdriver.py\", line 378, in execute\n    response = self.command_executor.execute(driver_command, params)\n  File \"C:\\Users\\Артём\\AppData\\Roaming\\Python\\Python310\\site-packages\\selenium\\webdriver\\remote\\remote_connection.py\", line 391, in execute\n    return self._request(command_info[0], url, body=data)\n  File \"C:\\Users\\Артём\\AppData\\Roaming\\Python\\Python310\\site-packages\\selenium\\webdriver\\remote\\remote_connection.py\", line 415, in _request\n    response = self._conn.request(method, url, body=body, headers=headers, timeout=self._client_config.timeout)\n  File \"C:\\Users\\Артём\\AppData\\Roaming\\Python\\Python310\\site-packages\\urllib3\\_request_methods.py\", line 135, in request\n    return self.request_encode_url(\n  File \"C:\\Users\\Артём\\AppData\\Roaming\\Python\\Python310\\site-packages\\urllib3\\_request_methods.py\", line 182, in request_encode_url\n    return self.urlopen(method, url, **extra_kw)\n  File \"C:\\Users\\Артём\\AppData\\Roaming\\Python\\Python310\\site-packages\\urllib3\\poolmanager.py\", line 443, in urlopen\n    response = conn.urlopen(method, u.request_uri, **kw)\n  File \"C:\\Users\\Артём\\AppData\\Roaming\\Python\\Python310\\site-packages\\urllib3\\connectionpool.py\", line 873, in urlopen\n    return self.urlopen(\n  File \"C:\\Users\\Артём\\AppData\\Roaming\\Python\\Python310\\site-packages\\urllib3\\connectionpool.py\", line 873, in urlopen\n    return self.urlopen(\n  File \"C:\\Users\\Артём\\AppData\\Roaming\\Python\\Python310\\site-packages\\urllib3\\connectionpool.py\", line 873, in urlopen\n    return self.urlopen(\n  File \"C:\\Users\\Артём\\AppData\\Roaming\\Python\\Python310\\site-packages\\urllib3\\connectionpool.py\", line 843, in urlopen\n    retries = retries.increment(\n  File \"C:\\Users\\Артём\\AppData\\Roaming\\Python\\Python310\\site-packages\\urllib3\\util\\retry.py\", line 519, in increment\n    raise MaxRetryError(_pool, url, reason) from reason  # type: ignore[arg-type]\n"}, "attachments": [{"name": "test_input_main_registration", "source": "88483d30-157c-4e0c-a187-36b42683557e-attachment.png", "type": "image/png"}], "start": 1736902078569, "stop": 1736902097287}], "start": 1736902028761, "stop": 1736902097287}